
============================================================
============================================================
Traceback (most recent call last):
  File "C:\Users\ricar\Documents\pegasus\pegasus\dados\load_all.py", line 220, in <module>
    load_any('dbsus4', 'postgres', '123456', datasus_db,ano, ano, exceptions)
  File "C:\Users\ricar\Documents\pegasus\pegasus\dados\load_all.py", line 174, in load_any
    main_table(df_arqs_nao_carregados.NOME[i], df_arqs_nao_carregados.DIRETORIO[i],
  File "C:\Users\ricar\Documents\pegasus\pegasus\dados\insertion\insert_into_any_CNES.py", line 605, in insert_into_main_table_and_arquivos
    counting_rows = pd.read_sql(f'''SELECT COUNT(*) from {child_db}.{main_table}''', con=device)
  File "C:\Users\ricar\Documents\pegasusenv\lib\site-packages\pandas\io\sql.py", line 590, in read_sql
    return pandas_sql.read_query(
  File "C:\Users\ricar\Documents\pegasusenv\lib\site-packages\pandas\io\sql.py", line 1560, in read_query
    result = self.execute(*args)
  File "C:\Users\ricar\Documents\pegasusenv\lib\site-packages\pandas\io\sql.py", line 1405, in execute
    return self.connectable.execution_options().execute(*args, **kwargs)
  File "<string>", line 2, in execute
  File "C:\Users\ricar\Documents\pegasusenv\lib\site-packages\sqlalchemy\util\deprecations.py", line 468, in warned
    return fn(*args, **kwargs)
  File "C:\Users\ricar\Documents\pegasusenv\lib\site-packages\sqlalchemy\engine\base.py", line 3257, in execute
    return connection.execute(statement, *multiparams, **params)
  File "C:\Users\ricar\Documents\pegasusenv\lib\site-packages\sqlalchemy\engine\base.py", line 1365, in execute
    return self._exec_driver_sql(
  File "C:\Users\ricar\Documents\pegasusenv\lib\site-packages\sqlalchemy\engine\base.py", line 1669, in _exec_driver_sql
    ret = self._execute_context(
  File "C:\Users\ricar\Documents\pegasusenv\lib\site-packages\sqlalchemy\engine\base.py", line 1943, in _execute_context
    self._handle_dbapi_exception(
  File "C:\Users\ricar\Documents\pegasusenv\lib\site-packages\sqlalchemy\engine\base.py", line 2128, in _handle_dbapi_exception
    util.raise_(exc_info[1], with_traceback=exc_info[2])
  File "C:\Users\ricar\Documents\pegasusenv\lib\site-packages\sqlalchemy\util\compat.py", line 211, in raise_
    raise exception
  File "C:\Users\ricar\Documents\pegasusenv\lib\site-packages\sqlalchemy\engine\base.py", line 1900, in _execute_context
    self.dialect.do_execute(
  File "C:\Users\ricar\Documents\pegasusenv\lib\site-packages\sqlalchemy\engine\default.py", line 736, in do_execute
    cursor.execute(statement, parameters)
  File "C:\Program Files\WindowsApps\PythonSoftwareFoundation.Python.3.9_3.9.3568.0_x64__qbz5n2kfra8p0\lib\encodings\utf_8.py", line 15, in decode
    def decode(input, errors='strict'):
KeyboardInterrupt
============================================================